<?xml version="1.0" ?>
<!-- =================================================================================== -->
<!-- |    This document was autogenerated by xacro from scara_v2_with_gripper_urdf.xacro | -->
<!-- |    EDITING THIS FILE BY HAND IS NOT RECOMMENDED                                 | -->
<!-- =================================================================================== -->
<robot name="scara_v2" xmlns:xacro="http://www.ros.org/wiki/xacro">
  <!--  Material Color definitions -->
  <material name="white">
    <color rgba="1 1 1 1"/>
  </material>
  <material name="blue">
    <color rgba="0 0 1 1"/>
  </material>
  <material name="red">
    <color rgba="1 0 0 1"/>
  </material>
  <material name="green">
    <color rgba="0 1 0 1"/>
  </material>
  <material name="sensoSilver">
    <color rgba="0.839216 0.839216 0.839216 1"/>
  </material>
  <material name="sensoBlack">
    <color rgba="0 0 0 1 "/>
  </material>
  <material name="sensoGray">
    <color rgba="0.466667 0.533333 0.6 1 "/>
  </material>
  <material name="sensoDarkGray">
    <color rgba="0.156863 0.156863 0.156863 1 "/>
  </material>
  <!--****************************-->
  <!--****************************-->
  <!-- Link and Joint definitions  -->
  <link name="world"/>
  <joint name="world_to_BaseBox" type="fixed">
    <parent link="world"/>
    <child link="BaseBox"/>
    <origin rpy="0 0 0" xyz="0 0 0.965"/>
    <axis xyz="1 0 0"/>
  </joint>
  <!--           TABLE             -->
  <link name="BaseBox">
    <inertial>
      <origin rpy="0 0 0" xyz="0 0 0"/>
      <mass value="1"/>
      <inertia ixx="1" ixy="0" ixz="0" iyy="1" iyz="0" izz="1"/>
    </inertial>
    <visual>
      <origin rpy="0 0 0" xyz="0 0 0"/>
      <geometry>
        <mesh filename="package://scara_v2_with_gripper/meshes/baseBox.STL"/>
      </geometry>
      <material name="sensoGray">
            </material>
    </visual>
    <collision>
      <origin rpy="0 0 0" xyz="0 0 0"/>
      <geometry>
        <!--?????????-->
        <mesh filename="package://scara_v2_with_gripper/meshes/baseBox_modif.stl"/>
      </geometry>
    </collision>
  </link>
  <link name="CentralStop1">
    <inertial>
      <origin rpy="0 0 0" xyz="0 0 0"/>
      <mass value="0"/>
      <inertia ixx="1" ixy="0" ixz="0" iyy="1" iyz="0" izz="1"/>
    </inertial>
    <visual>
      <origin rpy="0 0 0" xyz="0 0 0"/>
      <geometry>
        <mesh filename="package://scara_v2_with_gripper/meshes/CentralStop1.STL"/>
      </geometry>
      <material name="red">
            </material>
    </visual>
    <collision>
      <origin rpy="0 0 0" xyz="0 0 0"/>
      <geometry>
        <mesh filename="package://scara_v2_with_gripper/meshes/CentralStop1_modif.stl"/>
      </geometry>
    </collision>
  </link>
  <joint name="Joint_CentralStop1" type="fixed">
    <parent link="BaseBox"/>
    <child link="CentralStop1"/>
    <origin rpy="-3.8218E-18 -1.301E-16 -3.1416" xyz="0.69 0.11 -0.0015"/>
    <axis xyz="1 0 0"/>
  </joint>
  <link name="CentralStop2">
    <inertial>
      <origin rpy="0 0 0" xyz="0 0 0"/>
      <mass value="1"/>
      <inertia ixx="1" ixy="0" ixz="0" iyy="1" iyz="0" izz="1"/>
    </inertial>
    <visual>
      <origin rpy="0 0 0" xyz="0 0 0"/>
      <geometry>
        <mesh filename="package://scara_v2_with_gripper/meshes/CentralStop2.STL"/>
      </geometry>
      <material name="red">
            </material>
    </visual>
    <collision>
      <origin rpy="0 0 0" xyz="0 0 0"/>
      <geometry>
        <mesh filename="package://scara_v2_with_gripper/meshes/CentralStop2_modif.stl"/>
      </geometry>
    </collision>
  </link>
  <joint name="Joint_CentralStop2" type="fixed">
    <parent link="BaseBox"/>
    <child link="CentralStop2"/>
    <origin rpy="-3.8218E-18 -1.301E-16 -3.1416" xyz="0.69 1.05 -0.0015"/>
    <axis xyz="1 0 0"/>
  </joint>
  <!-- ******************************-->
  <!--             SCARA             -->
  <link name="ScaraBase">
    <inertial>
      <origin rpy="0 0 0" xyz="0 0 0"/>
      <mass value="1"/>
      <inertia ixx="1" ixy="0" ixz="0" iyy="1" iyz="0" izz="1"/>
    </inertial>
    <visual>
      <origin rpy="0 0 0" xyz="0 0 0"/>
      <geometry>
        <mesh filename="package://scara_v2_with_gripper/meshes/ScaraBase.STL"/>
      </geometry>
      <material name="sensoSilver">
            </material>
    </visual>
    <collision>
      <origin rpy="0 0 0" xyz="0 0 0"/>
      <geometry>
        <mesh filename="package://scara_v2_with_gripper/meshes/ScaraBase.STL"/>
      </geometry>
    </collision>
  </link>
  <joint name="Joint_ScaraBase" type="fixed">
    <parent link="BaseBox"/>
    <child link="ScaraBase"/>
    <origin rpy="1.5708 0 0" xyz="0.212 0.58 0.141"/>
    <axis xyz="1 0 0"/>
  </joint>
  <link name="ScaraLink1">
    <inertial>
      <origin rpy="-1.57 0 0" xyz="0 0 0"/>
      <mass value="3.8063"/>
      <inertia ixx="7.8753E-3" ixy="4.6431E-3" ixz="-1.4702E-5" iyy="6.1309E-2" iyz="-5.8992E-6" izz="6.2681E-2"/>
    </inertial>
    <visual>
      <origin rpy="-1.57 0 0" xyz="0 0 0"/>
      <geometry>
        <mesh filename="package://scara_v2_with_gripper/meshes/ScaraLink1.STL"/>
        <!--ScaraLink1.STL-->
      </geometry>
      <material name="sensoSilver">
            </material>
    </visual>
    <collision>
      <origin rpy="-1.57 0 0" xyz="0 0 0"/>
      <geometry>
        <mesh filename="package://scara_v2_with_gripper/meshes/ScaraLink1.STL"/>
      </geometry>
    </collision>
  </link>
  <joint name="Joint1" type="revolute">
    <parent link="ScaraBase"/>
    <child link="ScaraLink1"/>
    <origin rpy="1.57 0 0" xyz="0 0.051 0"/>
    <axis xyz="0 0 1"/>
    <!--<limit effort="0" lower="-1.57079" upper="1.57079" velocity="0"/>-->
    <limit effort="0" lower="-1.4835298642" upper="1.4835298642" velocity="0"/>
  </joint>
  <link name="ScaraLink2">
    <inertial>
      <origin rpy="1.57 1.57 0" xyz="0 0 0"/>
      <mass value="1.5020"/>
      <inertia ixx="5.0471E-2" ixy="3.0689E-4" ixz="-8.5622E-4" iyy="4.7456E-2" iyz="8.7643E-3" izz="5.2228E-3"/>
    </inertial>
    <visual>
      <origin rpy="1.57 0 0" xyz="0 0 0"/>
      <geometry>
        <mesh filename="package://scara_v2_with_gripper/meshes/ScaraLink2.STL"/>
      </geometry>
      <material name="sensoSilver">
            </material>
    </visual>
    <collision>
      <origin rpy="0 1.57 0" xyz="0 0 0"/>
      <geometry>
        <mesh filename="package://scara_v2_with_gripper/meshes/ScaraLink2.STL"/>
      </geometry>
    </collision>
  </link>
  <joint name="Joint2" type="revolute">
    <parent link="ScaraLink1"/>
    <child link="ScaraLink2"/>
    <origin rpy="0 0 1.57" xyz="0.24972  0 0.081"/>
    <axis xyz="0 0 1"/>
    <!--<limit effort="0" lower="-2.65" upper="2.65" velocity="0"/>-->
    <limit effort="0" lower="-2.9670597284" upper="2.9670597284" velocity="0"/>
  </joint>
  <!--**********************************-->
  <!--     GRIPPER JOINTS DEFINITION    -->
  <!--Revolute joint for IKfast-->
  <link name="fake_link"/>
  <joint name="fake_joint" type="revolute">
    <parent link="ScaraLink2"/>
    <child link="fake_link"/>
    <!--<origin xyz="0 -0.24305 0.0424 " rpy="0 0 3.1416" />-->
    <origin rpy="0 0 3.1416" xyz="0 -0.24305 -0.0424 "/>
    <axis xyz="0 0 1"/>
    <limit effort="1000.0" lower="0.0" upper="0.001" velocity="0"/>
  </joint>
  <link name="GripperBase">
    <inertial>
      <origin rpy="1.57 0 0" xyz="0 0 0"/>
      <mass value="1"/>
      <inertia ixx="1E-6" ixy="0" ixz="0" iyy="1E-6" iyz="0" izz="1E-6"/>
    </inertial>
    <visual>
      <origin rpy="1.57 0 0" xyz="0 0 0"/>
      <geometry>
        <mesh filename="package://scara_v2_with_gripper/meshes/GripperBase.STL"/>
      </geometry>
      <material name="sensoDarkGray">
            </material>
    </visual>
    <collision>
      <origin rpy="1.57 0 0" xyz="0 0 0"/>
      <geometry>
        <mesh filename="package://scara_v2_with_gripper/meshes/GripperBase.STL"/>
      </geometry>
    </collision>
  </link>
  <joint name="Joint_GripperBase" type="prismatic">
    <parent link="fake_link"/>
    <child link="GripperBase"/>
    <origin rpy="0 0 0" xyz="0 0 0"/>
    <!--<origin xyz="0 -0.0424 0.24305" rpy="3.1416 0 3.1416" />-->
    <axis xyz="0 0 1"/>
    <limit effort="1000.0" lower="-0.04" upper="0.05" velocity="1"/>
  </joint>
  <link name="tool0"/>
  <joint name="Base_to_tool0" type="fixed">
    <parent link="GripperBase"/>
    <child link="tool0"/>
    <origin rpy="0 0 0 " xyz="0 0 0.0984"/>
    <axis xyz="0 0 0"/>
  </joint>
  <link name="GripperLeft">
    <inertial>
      <origin rpy="3.14 0 0" xyz="0 0 0"/>
      <mass value="1"/>
      <inertia ixx="1E-6" ixy="0" ixz="0" iyy="1E-6" iyz="0" izz="1E-6"/>
    </inertial>
    <visual>
      <origin rpy="3.14 0 0" xyz="0 0 0"/>
      <geometry>
        <mesh filename="package://scara_v2_with_gripper/meshes/gripperLeft_full.STL"/>
      </geometry>
      <material name="sensoDarkGray">
            </material>
    </visual>
    <collision>
      <origin rpy="3.14 0 0" xyz="0 0 0"/>
      <geometry>
        <mesh filename="package://scara_v2_with_gripper/meshes/gripperLeft_full.STL"/>
      </geometry>
    </collision>
  </link>
  <joint name="Joint_Gripper" type="prismatic">
    <parent link="GripperBase"/>
    <child link="GripperLeft"/>
    <origin rpy="-1.57 0 0" xyz="-0.0162 0 0.0984"/>
    <axis xyz="1 0 0"/>
    <limit effort="1000.0" lower="0" upper="0.003" velocity="1"/>
  </joint>
  <link name="GripperRight">
    <inertial>
      <origin rpy="3.14 0 0" xyz="0 0 0"/>
      <mass value="1"/>
      <inertia ixx="1E-6" ixy="0" ixz="0" iyy="1E-6" iyz="0" izz="1E-6"/>
    </inertial>
    <visual>
      <origin rpy="3.14 0 0" xyz="0 0 0"/>
      <geometry>
        <mesh filename="package://scara_v2_with_gripper/meshes/gripperRight_full.STL"/>
      </geometry>
      <material name="sensoDarkGray">
            </material>
    </visual>
    <collision>
      <origin rpy="3.14 0 0" xyz="0 0 0"/>
      <geometry>
        <mesh filename="package://scara_v2_with_gripper/meshes/gripperRight_full.STL"/>
      </geometry>
    </collision>
  </link>
  <joint name="Joint_GripperRight" type="prismatic">
    <parent link="GripperBase"/>
    <child link="GripperRight"/>
    <origin rpy="1.57 0 3.1416" xyz="0.0165 0 0.0984"/>
    <axis xyz="1 0 0"/>
    <limit effort="1000.0" lower="0" upper="0.003" velocity="1"/>
    <mimic joint="Joint_Gripper" multiplier="1" offset="0"/>
  </joint>
</robot>

